2020-07-01 15:40:46,390 :: play_game_random :: line: 1874 :: INFO :: Book move is d7d5.
2020-07-01 15:40:47,632 :: play_game_random :: line: 1874 :: INFO :: Book move is g7g6.
2020-07-01 15:40:48,864 :: get_book_move :: line: 293 :: WARNING :: No more book move.
2020-07-01 15:40:48,864 :: play_game_random :: line: 1874 :: INFO :: Book move is None.
2020-07-01 15:40:48,865 :: __init__ :: line: 485 :: DEBUG :: Using proactor: IocpProactor
2020-07-01 15:40:48,872 :: run :: line: 458 :: ERROR :: Failed to start C:/Users/lf947/Documents/M2 IASD/Monte_Carlo/Python-Easy-Chess-GUI-master/Engines/CDrill_1800_32bit.exe.
Traceback (most recent call last):
  File "MChess.py", line 448, in run
    creationflags=subprocess.CREATE_NO_WINDOW)
  File "C:\Users\lf947\Anaconda3\lib\site-packages\chess\engine.py", line 2440, in popen_uci
    return cls.popen(UciProtocol, command, timeout=timeout, debug=debug, setpgrp=setpgrp, **popen_args)
  File "C:\Users\lf947\Anaconda3\lib\site-packages\chess\engine.py", line 2432, in popen
    return run_in_background(background, name=f"{cls.__name__} (command={command!r})", debug=debug)
  File "C:\Users\lf947\Anaconda3\lib\site-packages\chess\engine.py", line 217, in run_in_background
    return future.result()
  File "C:\Users\lf947\Anaconda3\lib\concurrent\futures\_base.py", line 435, in result
    return self.__get_result()
  File "C:\Users\lf947\Anaconda3\lib\concurrent\futures\_base.py", line 384, in __get_result
    raise self._exception
  File "C:\Users\lf947\Anaconda3\lib\site-packages\chess\engine.py", line 211, in background
    _run(coroutine(future))
  File "C:\Users\lf947\Anaconda3\lib\asyncio\runners.py", line 43, in run
    return loop.run_until_complete(main)
  File "C:\Users\lf947\Anaconda3\lib\asyncio\base_events.py", line 579, in run_until_complete
    return future.result()
  File "C:\Users\lf947\Anaconda3\lib\site-packages\chess\engine.py", line 2420, in background
    transport, protocol = await Protocol.popen(command, setpgrp=setpgrp, **popen_args)
  File "C:\Users\lf947\Anaconda3\lib\site-packages\chess\engine.py", line 912, in popen
    return await _get_running_loop().subprocess_exec(cls, *command, **popen_args)  # type: ignore
  File "C:\Users\lf947\Anaconda3\lib\asyncio\base_events.py", line 1529, in subprocess_exec
    bufsize, **kwargs)
  File "C:\Users\lf947\Anaconda3\lib\asyncio\windows_events.py", line 372, in _make_subprocess_transport
    **kwargs)
  File "C:\Users\lf947\Anaconda3\lib\asyncio\base_subprocess.py", line 37, in __init__
    stderr=stderr, bufsize=bufsize, **kwargs)
  File "C:\Users\lf947\Anaconda3\lib\asyncio\windows_events.py", line 819, in _start
    bufsize=bufsize, **kwargs)
  File "C:\Users\lf947\Anaconda3\lib\asyncio\windows_utils.py", line 155, in __init__
    stderr=stderr_wfd, **kwds)
  File "C:\Users\lf947\Anaconda3\lib\subprocess.py", line 775, in __init__
    restore_signals, start_new_session)
  File "C:\Users\lf947\Anaconda3\lib\subprocess.py", line 1178, in _execute_child
    startupinfo)
FileNotFoundError: [WinError 2] Le fichier spécifié est introuvable
2020-07-01 15:40:48,970 :: update_text_box :: line: 1271 :: ERROR :: Engine sent None.
Traceback (most recent call last):
  File "MChess.py", line 1269, in update_text_box
    best_move = chess.Move.from_uci(msg.split()[1])
  File "C:\Users\lf947\Anaconda3\lib\site-packages\chess\__init__.py", line 509, in from_uci
    from_square = SQUARE_NAMES.index(uci[0:2])
ValueError: 'No' is not in list
2020-07-01 15:40:59,339 :: play_game_random :: line: 1984 :: INFO :: engine msg: bestmove None
2020-07-01 15:40:59,339 :: quit_engine :: line: 605 :: INFO :: quit engine
2020-07-01 15:40:59,339 :: quit_engine :: line: 609 :: INFO :: AttributeError, self.engine is already None
2020-07-01 15:40:59,339 :: play_game_random :: line: 2071 :: INFO :: Saving game automatically
2020-07-01 15:41:00,934 :: main_loop :: line: 3086 :: INFO :: Quit app from main loop, X is pressed.
